Internal Server Error: /asahiyaki/select_front/
"POST /asahiyaki/select_front/?uuid=45fbadb1-6bd0-4d57-b3c0-89fb7dd73dc6 HTTP/1.1" 500 66
Internal Server Error: /asahiyaki/select_front/
"POST /asahiyaki/select_front/?uuid=45fbadb1-6bd0-4d57-b3c0-89fb7dd73dc6 HTTP/1.1" 500 66
Internal Server Error: /asahiyaki/select_front/
"POST /asahiyaki/select_front/?uuid=45fbadb1-6bd0-4d57-b3c0-89fb7dd73dc6 HTTP/1.1" 500 66
Internal Server Error: /asahiyaki/select_front/
"POST /asahiyaki/select_front/?uuid=45fbadb1-6bd0-4d57-b3c0-89fb7dd73dc6 HTTP/1.1" 500 66
Internal Server Error: /asahiyaki/select_front/
"POST /asahiyaki/select_front/?uuid=45fbadb1-6bd0-4d57-b3c0-89fb7dd73dc6 HTTP/1.1" 500 66
Internal Server Error: /asahiyaki/select_front/
"POST /asahiyaki/select_front/?uuid=45fbadb1-6bd0-4d57-b3c0-89fb7dd73dc6 HTTP/1.1" 500 66
Internal Server Error: /asahiyaki/select_front/
"POST /asahiyaki/select_front/?uuid=45fbadb1-6bd0-4d57-b3c0-89fb7dd73dc6 HTTP/1.1" 500 66
Internal Server Error: /asahiyaki/select_front/
"POST /asahiyaki/select_front/?uuid=45fbadb1-6bd0-4d57-b3c0-89fb7dd73dc6 HTTP/1.1" 500 66
Internal Server Error: /admin/render/asahiyaki/add/
Traceback (most recent call last):
  File "/usr/local/lib/python3.9/site-packages/django/db/backends/utils.py", line 89, in _execute
    return self.cursor.execute(sql, params)
psycopg2.errors.UniqueViolation: duplicate key value violates unique constraint "render_asahiyaki_pkey"
DETAIL:  Key (id)=(12) already exists.


The above exception was the direct cause of the following exception:

Traceback (most recent call last):
  File "/usr/local/lib/python3.9/site-packages/django/core/handlers/exception.py", line 55, in inner
    response = get_response(request)
  File "/usr/local/lib/python3.9/site-packages/django/core/handlers/base.py", line 197, in _get_response
    response = wrapped_callback(request, *callback_args, **callback_kwargs)
  File "/usr/local/lib/python3.9/site-packages/django/contrib/admin/options.py", line 688, in wrapper
    return self.admin_site.admin_view(view)(*args, **kwargs)
  File "/usr/local/lib/python3.9/site-packages/django/utils/decorators.py", line 134, in _wrapper_view
    response = view_func(request, *args, **kwargs)
  File "/usr/local/lib/python3.9/site-packages/django/views/decorators/cache.py", line 62, in _wrapper_view_func
    response = view_func(request, *args, **kwargs)
  File "/usr/local/lib/python3.9/site-packages/django/contrib/admin/sites.py", line 242, in inner
    return view(request, *args, **kwargs)
  File "/usr/local/lib/python3.9/site-packages/django/contrib/admin/options.py", line 1886, in add_view
    return self.changeform_view(request, None, form_url, extra_context)
  File "/usr/local/lib/python3.9/site-packages/django/utils/decorators.py", line 46, in _wrapper
    return bound_method(*args, **kwargs)
  File "/usr/local/lib/python3.9/site-packages/django/utils/decorators.py", line 134, in _wrapper_view
    response = view_func(request, *args, **kwargs)
  File "/usr/local/lib/python3.9/site-packages/django/contrib/admin/options.py", line 1747, in changeform_view
    return self._changeform_view(request, object_id, form_url, extra_context)
  File "/usr/local/lib/python3.9/site-packages/django/contrib/admin/options.py", line 1798, in _changeform_view
    self.save_model(request, new_object, form, not add)
  File "/usr/local/lib/python3.9/site-packages/django/contrib/admin/options.py", line 1227, in save_model
    obj.save()
  File "/usr/local/lib/python3.9/site-packages/django/db/models/base.py", line 814, in save
    self.save_base(
  File "/usr/local/lib/python3.9/site-packages/django/db/models/base.py", line 877, in save_base
    updated = self._save_table(
  File "/usr/local/lib/python3.9/site-packages/django/db/models/base.py", line 1020, in _save_table
    results = self._do_insert(
  File "/usr/local/lib/python3.9/site-packages/django/db/models/base.py", line 1061, in _do_insert
    return manager._insert(
  File "/usr/local/lib/python3.9/site-packages/django/db/models/manager.py", line 87, in manager_method
    return getattr(self.get_queryset(), name)(*args, **kwargs)
  File "/usr/local/lib/python3.9/site-packages/django/db/models/query.py", line 1805, in _insert
    return query.get_compiler(using=using).execute_sql(returning_fields)
  File "/usr/local/lib/python3.9/site-packages/django/db/models/sql/compiler.py", line 1820, in execute_sql
    cursor.execute(sql, params)
  File "/usr/local/lib/python3.9/site-packages/django/db/backends/utils.py", line 102, in execute
    return super().execute(sql, params)
  File "/usr/local/lib/python3.9/site-packages/django/db/backends/utils.py", line 67, in execute
    return self._execute_with_wrappers(
  File "/usr/local/lib/python3.9/site-packages/django/db/backends/utils.py", line 80, in _execute_with_wrappers
    return executor(sql, params, many, context)
  File "/usr/local/lib/python3.9/site-packages/django/db/backends/utils.py", line 89, in _execute
    return self.cursor.execute(sql, params)
  File "/usr/local/lib/python3.9/site-packages/django/db/utils.py", line 91, in __exit__
    raise dj_exc_value.with_traceback(traceback) from exc_value
  File "/usr/local/lib/python3.9/site-packages/django/db/backends/utils.py", line 89, in _execute
    return self.cursor.execute(sql, params)
django.db.utils.IntegrityError: duplicate key value violates unique constraint "render_asahiyaki_pkey"
DETAIL:  Key (id)=(12) already exists.

"POST /admin/render/asahiyaki/add/ HTTP/1.1" 500 174624
Internal Server Error: /admin/render/asahiyaki/add/
Traceback (most recent call last):
  File "/usr/local/lib/python3.9/site-packages/django/db/backends/utils.py", line 89, in _execute
    return self.cursor.execute(sql, params)
psycopg2.errors.UniqueViolation: duplicate key value violates unique constraint "render_asahiyaki_pkey"
DETAIL:  Key (id)=(13) already exists.


The above exception was the direct cause of the following exception:

Traceback (most recent call last):
  File "/usr/local/lib/python3.9/site-packages/django/core/handlers/exception.py", line 55, in inner
    response = get_response(request)
  File "/usr/local/lib/python3.9/site-packages/django/core/handlers/base.py", line 197, in _get_response
    response = wrapped_callback(request, *callback_args, **callback_kwargs)
  File "/usr/local/lib/python3.9/site-packages/django/contrib/admin/options.py", line 688, in wrapper
    return self.admin_site.admin_view(view)(*args, **kwargs)
  File "/usr/local/lib/python3.9/site-packages/django/utils/decorators.py", line 134, in _wrapper_view
    response = view_func(request, *args, **kwargs)
  File "/usr/local/lib/python3.9/site-packages/django/views/decorators/cache.py", line 62, in _wrapper_view_func
    response = view_func(request, *args, **kwargs)
  File "/usr/local/lib/python3.9/site-packages/django/contrib/admin/sites.py", line 242, in inner
    return view(request, *args, **kwargs)
  File "/usr/local/lib/python3.9/site-packages/django/contrib/admin/options.py", line 1886, in add_view
    return self.changeform_view(request, None, form_url, extra_context)
  File "/usr/local/lib/python3.9/site-packages/django/utils/decorators.py", line 46, in _wrapper
    return bound_method(*args, **kwargs)
  File "/usr/local/lib/python3.9/site-packages/django/utils/decorators.py", line 134, in _wrapper_view
    response = view_func(request, *args, **kwargs)
  File "/usr/local/lib/python3.9/site-packages/django/contrib/admin/options.py", line 1747, in changeform_view
    return self._changeform_view(request, object_id, form_url, extra_context)
  File "/usr/local/lib/python3.9/site-packages/django/contrib/admin/options.py", line 1798, in _changeform_view
    self.save_model(request, new_object, form, not add)
  File "/usr/local/lib/python3.9/site-packages/django/contrib/admin/options.py", line 1227, in save_model
    obj.save()
  File "/usr/local/lib/python3.9/site-packages/django/db/models/base.py", line 814, in save
    self.save_base(
  File "/usr/local/lib/python3.9/site-packages/django/db/models/base.py", line 877, in save_base
    updated = self._save_table(
  File "/usr/local/lib/python3.9/site-packages/django/db/models/base.py", line 1020, in _save_table
    results = self._do_insert(
  File "/usr/local/lib/python3.9/site-packages/django/db/models/base.py", line 1061, in _do_insert
    return manager._insert(
  File "/usr/local/lib/python3.9/site-packages/django/db/models/manager.py", line 87, in manager_method
    return getattr(self.get_queryset(), name)(*args, **kwargs)
  File "/usr/local/lib/python3.9/site-packages/django/db/models/query.py", line 1805, in _insert
    return query.get_compiler(using=using).execute_sql(returning_fields)
  File "/usr/local/lib/python3.9/site-packages/django/db/models/sql/compiler.py", line 1820, in execute_sql
    cursor.execute(sql, params)
  File "/usr/local/lib/python3.9/site-packages/django/db/backends/utils.py", line 102, in execute
    return super().execute(sql, params)
  File "/usr/local/lib/python3.9/site-packages/django/db/backends/utils.py", line 67, in execute
    return self._execute_with_wrappers(
  File "/usr/local/lib/python3.9/site-packages/django/db/backends/utils.py", line 80, in _execute_with_wrappers
    return executor(sql, params, many, context)
  File "/usr/local/lib/python3.9/site-packages/django/db/backends/utils.py", line 89, in _execute
    return self.cursor.execute(sql, params)
  File "/usr/local/lib/python3.9/site-packages/django/db/utils.py", line 91, in __exit__
    raise dj_exc_value.with_traceback(traceback) from exc_value
  File "/usr/local/lib/python3.9/site-packages/django/db/backends/utils.py", line 89, in _execute
    return self.cursor.execute(sql, params)
django.db.utils.IntegrityError: duplicate key value violates unique constraint "render_asahiyaki_pkey"
DETAIL:  Key (id)=(13) already exists.

"POST /admin/render/asahiyaki/add/ HTTP/1.1" 500 174672
Internal Server Error: /admin/render/asahiyaki/add/
Traceback (most recent call last):
  File "/usr/local/lib/python3.9/site-packages/django/db/backends/utils.py", line 89, in _execute
    return self.cursor.execute(sql, params)
psycopg2.errors.UniqueViolation: duplicate key value violates unique constraint "render_asahiyaki_pkey"
DETAIL:  Key (id)=(14) already exists.


The above exception was the direct cause of the following exception:

Traceback (most recent call last):
  File "/usr/local/lib/python3.9/site-packages/django/core/handlers/exception.py", line 55, in inner
    response = get_response(request)
  File "/usr/local/lib/python3.9/site-packages/django/core/handlers/base.py", line 197, in _get_response
    response = wrapped_callback(request, *callback_args, **callback_kwargs)
  File "/usr/local/lib/python3.9/site-packages/django/contrib/admin/options.py", line 688, in wrapper
    return self.admin_site.admin_view(view)(*args, **kwargs)
  File "/usr/local/lib/python3.9/site-packages/django/utils/decorators.py", line 134, in _wrapper_view
    response = view_func(request, *args, **kwargs)
  File "/usr/local/lib/python3.9/site-packages/django/views/decorators/cache.py", line 62, in _wrapper_view_func
    response = view_func(request, *args, **kwargs)
  File "/usr/local/lib/python3.9/site-packages/django/contrib/admin/sites.py", line 242, in inner
    return view(request, *args, **kwargs)
  File "/usr/local/lib/python3.9/site-packages/django/contrib/admin/options.py", line 1886, in add_view
    return self.changeform_view(request, None, form_url, extra_context)
  File "/usr/local/lib/python3.9/site-packages/django/utils/decorators.py", line 46, in _wrapper
    return bound_method(*args, **kwargs)
  File "/usr/local/lib/python3.9/site-packages/django/utils/decorators.py", line 134, in _wrapper_view
    response = view_func(request, *args, **kwargs)
  File "/usr/local/lib/python3.9/site-packages/django/contrib/admin/options.py", line 1747, in changeform_view
    return self._changeform_view(request, object_id, form_url, extra_context)
  File "/usr/local/lib/python3.9/site-packages/django/contrib/admin/options.py", line 1798, in _changeform_view
    self.save_model(request, new_object, form, not add)
  File "/usr/local/lib/python3.9/site-packages/django/contrib/admin/options.py", line 1227, in save_model
    obj.save()
  File "/usr/local/lib/python3.9/site-packages/django/db/models/base.py", line 814, in save
    self.save_base(
  File "/usr/local/lib/python3.9/site-packages/django/db/models/base.py", line 877, in save_base
    updated = self._save_table(
  File "/usr/local/lib/python3.9/site-packages/django/db/models/base.py", line 1020, in _save_table
    results = self._do_insert(
  File "/usr/local/lib/python3.9/site-packages/django/db/models/base.py", line 1061, in _do_insert
    return manager._insert(
  File "/usr/local/lib/python3.9/site-packages/django/db/models/manager.py", line 87, in manager_method
    return getattr(self.get_queryset(), name)(*args, **kwargs)
  File "/usr/local/lib/python3.9/site-packages/django/db/models/query.py", line 1805, in _insert
    return query.get_compiler(using=using).execute_sql(returning_fields)
  File "/usr/local/lib/python3.9/site-packages/django/db/models/sql/compiler.py", line 1820, in execute_sql
    cursor.execute(sql, params)
  File "/usr/local/lib/python3.9/site-packages/django/db/backends/utils.py", line 102, in execute
    return super().execute(sql, params)
  File "/usr/local/lib/python3.9/site-packages/django/db/backends/utils.py", line 67, in execute
    return self._execute_with_wrappers(
  File "/usr/local/lib/python3.9/site-packages/django/db/backends/utils.py", line 80, in _execute_with_wrappers
    return executor(sql, params, many, context)
  File "/usr/local/lib/python3.9/site-packages/django/db/backends/utils.py", line 89, in _execute
    return self.cursor.execute(sql, params)
  File "/usr/local/lib/python3.9/site-packages/django/db/utils.py", line 91, in __exit__
    raise dj_exc_value.with_traceback(traceback) from exc_value
  File "/usr/local/lib/python3.9/site-packages/django/db/backends/utils.py", line 89, in _execute
    return self.cursor.execute(sql, params)
django.db.utils.IntegrityError: duplicate key value violates unique constraint "render_asahiyaki_pkey"
DETAIL:  Key (id)=(14) already exists.

"POST /admin/render/asahiyaki/add/ HTTP/1.1" 500 174323
